Workbook
Name Empress: Analysis!$F$1
Name Empress: oldAnalysis!$E$1
Name Seductress: Analysis!$H$1
Name Seductress: oldAnalysis!$G$1

Sheet Epitome Archetype Guide
A1: Response ID | B1: Date Created | C1: Date Modified | D1: IP Address | E1: Duration (sec) | F1: Response Status | G1: Email | H1: First Name | I1: Last Name | J1: Collector ID | K1: Collector Type | L1: Custom Value | M1: Name | First name | N1: Name | Last name | O1: Email address | Email address | P1: Organization | Q1: What do you draw on to lead your team to deliver the optimum results? | Determination, charisma, and an innate understanding of the organization’s power structures | R1: What do you draw on to lead your team to deliver the optimum results? | An inspiring passion and intuitive understanding of individual and team dynamics | S1: What do you draw on to lead your team to deliver the optimum results? | The wisdom of my experience and an understanding of team dynamic | T1: What do you draw on to lead your team to deliver the optimum results? | The ability to amplify the reach of my boss and provide the behind the scenes insights | U1: What do you most trust when making decisions? | Information, evidence, and the informed insights from others that I trust | V1: What do you most trust when making decisions? | My instinct and gut in making sense of data and evidence and collaborating with others to assist me | W1: What do you most trust when making decisions? | My ability to understand the implications of information and which stakeholders need to be included in the decision-making process | X1: What do you most trust when making decisions? | My network’s strategic knowledge and my innate understanding of what they need to get the job done | Y1: What constrains me in work situations? | Chaos where the ultimate decision makers are not willing to make clear, tough decisions | Z1: What constrains me in work situations? | Lack of access to corporate knowledge and being sidelined from the decision-making process | AA1: What constrains me in work situations? | Over-reliance on cold, hard facts with little nuanced understanding of the people impact | AB1: What constrains me in work situations? | Lack of opportunity and an inability to have a visible and powerful impact | AC1: What inspires me in a senior leader? | An inspirational and passionate big picture thinker who understands the power of the team to realise significant objectives | AD1: What inspires me in a senior leader? | A compelling and strategic thinker who galvanises the team to execute with precision | AE1: What inspires me in a senior leader? | One that has a clear and captivating vision and recognizes and relies on my talents to execute on their strategy | AF1: What inspires me in a senior leader? | One that is powerful and has a magnetic vision and recognizes and celebrates my talent and ambition in driving results | AG1: As a leader, how do you manage challenges and setbacks? | I rally the team to tackle the challenge and work together to ensure our success through innovative execution | AH1: As a leader, how do you manage challenges and setbacks? | I figure out the key concerns that the leader has and work to address these to ensure a successful outcome | AI1: As a leader, how do you manage challenges and setbacks? | I clarify the reasons for the challenge, bolster the team where necessary, and double down on execution to ensure my success | AJ1: As a leader, how do you manage challenges and setbacks? | I focus on understanding the cause and systematically mitigate the challenge to set us up for success | AK1: How do work colleagues describe you? | As an influential, power behind the scenes and connected leader | AL1: How do work colleagues describe you? | As a passionate, inspiring and intuitive leader | AM1: How do work colleagues describe you? | As a wise, calm, and natural leader | AN1: How do work colleagues describe you? | As a charismatic, driven, and determined leader | AO1: What do you strive for in your role? | To build high performing teams that drive systemic, evidence-based, impactful outcomes | AP1: What do you strive for in your role? | To achieve the best outcome for my boss which bolster the organization’s strategy and benefits its people | AQ1: What do you strive for in your role? | To be the best by using my ambition and talent to achieve strategic corporate goals | AR1: What do you strive for in your role? | To bring together outstanding tight-knit teams with healthy cultures to deliver innovative, impactful results | AS1: How do you behave when working with your peers? | I lead with passion, an inspiring narrative, and galvanize the team through a deep intuitive understanding of individual and team dynamics | AT1: How do you behave when working with your peers? | I lead with analytic clarity, experiential wisdom, and a deep awareness of the team dynamic and how to harness this | AU1: How do you behave when working with your peers? | I lead with charisma, the ability to influence and shape the team, and a single-minded determination to deliver | AV1: How do you behave when working with your peers? | I lead by presenting the objectives of the organization and the goals of my boss and engage the team to ensure execution is the focus | AW1: How would you describe yourself at your worst (under pressure / bored / unhappy)? | Manipulative, political, demanding, icy, envious, furious, and a “win or die” attitude | AX1: How would you describe yourself at your worst (under pressure / bored / unhappy)? | Over-emotional, self-obsessed, easily enraged, scattered, cliquish, destructive, and hell-bent | AY1: How would you describe yourself at your worst (under pressure / bored / unhappy)? | Anxious, blinded by the loyalty to my boss, officious, dismissive, and passive aggressive | AZ1: How would you describe yourself at your worst (under pressure / bored / unhappy)? | Cold, disdainful, intimidating, unforgiving, and overly reliant on hard facts | BA1: What gives you confidence when acting in a leadership role? | The deep, intuitive understanding of what is at play, the creative and innovative capabilities I have, and my passion to make it happen | BB1: What gives you confidence when acting in a leadership role? | My self-belief and appreciation of my talent and a determination to be the very best at whatever I put my mind to | BC1: What gives you confidence when acting in a leadership role? | The belief in my capabilities, an understanding of the data, and a clear understanding of what needs to be achieved | BD1: What gives you confidence when acting in a leadership role? | The trust and belief that my leader has in me and my innate abilities to translate their vision into an exceptional performance | BE1: How do you relate to power in your leadership role? | My power lives in my people. I am genuinely most powerful in a collective, and I build teams that are greater than the sum of their parts | BF1: How do you relate to power in your leadership role? | I hold power with quiet authority. I know I have it, I do not need to demonstrate it, and I use it to create clarity and direction for those around me | BG1: How do you relate to power in your leadership role? | My power is relational, it flows from my deep understanding of my leader and organisation, and I am most effective when that relationship is strong and trusted | BH1: How do you relate to power in your leadership role? | I understand power instinctively - where it sits, how it moves, and how to position myself within it to achieve what I am here to achieve | BI1: How would you describe your relationship with ambition? | My ambition is channelled through my commitment to my leader and the organisation. I measure success by the quality and success of what we achieve together | BJ1: How would you describe your relationship with ambition? | I am unambiguously ambitious - for impact, for recognition, for being at the centre of what matters, and for making an impact. And I make no apology for that | BK1: How would you describe your relationship with ambition? | My ambition is for the collective. I want to build teams and cultures where people genuinely thrive, and that matters to me as much as any metric | BL1: How would you describe your relationship with ambition? | I am ambitious for outcomes and legacy. I believe in stewardship and want to build something that outlasts me. I hold a long view of what success looks like
A2: 119117321355 | B2: 46154.565 | C2: 46154.566 | D2: 58.169.214.233 | E2: 35 | F2: completed | G2: Not Answered | H2: Not Answered | I2: Not Answered | J2: 464641143 | K2: weblink | L2: Not Answered | M2: Laura | N2: Taitz | O2: laura.taitz@gmail.com | P2: Fraction PM | Q2: 1 | R2: 2 | S2: 3 | T2: 4 | U2: 1 | V2: 2 | W2: 3 | X2: 4 | Y2: 1 | Z2: 2 | AA2: 3 | AB2: 4 | AC2: 1 | AD2: 2 | AE2: 3 | AF2: 4 | AG2: 1 | AH2: 2 | AI2: 3 | AJ2: 4 | AK2: 1 | AL2: 2 | AM2: 3 | AN2: 4 | AO2: 1 | AP2: 2 | AQ2: 3 | AR2: 4 | AS2: 1 | AT2: 2 | AU2: 3 | AV2: 4 | AW2: 1 | AX2: 2 | AY2: 3 | AZ2: 4 | BA2: 1 | BB2: 2 | BC2: 3 | BD2: 4 | BE2: 1 | BF2: 2 | BG2: 3 | BH2: 4 | BI2: 1 | BJ2: 2 | BK2: 3 | BL2: 4
A3: 119117347207 | B3: 46154.62 | C3: 46154.622 | D3: 120.155.17.225 | E3: 185 | F3: completed | G3: Not Answered | H3: Not Answered | I3: Not Answered | J3: 464641143 | K3: weblink | L3: Not Answered | M3: Merle | N3: Singer | O3: merle@epitome-leadership.com | P3: Epitome Leadership | Q3: 4 | R3: 1 | S3: 2 | T3: 3 | U3: 3 | V3: 1 | W3: 4 | X3: 2 | Y3: 1 | Z3: 3 | AA3: 2 | AB3: 4 | AC3: 3 | AD3: 1 | AE3: 4 | AF3: 2 | AG3: 1 | AH3: 3 | AI3: 2 | AJ3: 4 | AK3: 3 | AL3: 1 | AM3: 2 | AN3: 4 | AO3: 1 | AP3: 3 | AQ3: 2 | AR3: 4 | AS3: 1 | AT3: 3 | AU3: 2 | AV3: 4 | AW3: 2 | AX3: 3 | AY3: 1 | AZ3: 4 | BA3: 1 | BB3: 4 | BC3: 2 | BD3: 3 | BE3: 4 | BF3: 3 | BG3: 1 | BH3: 2 | BI3: 4 | BJ3: 3 | BK3: 2 | BL3: 1
A4: 119138094925 | B4: 46183.783 | C4: 46183.8 | D4: 119.18.20.123 | E4: 1386 | F4: completed | G4: Not Answered | H4: Not Answered | I4: Not Answered | J4: 464641143 | K4: weblink | L4: Not Answered | M4: Jenny | N4: Nola | O4: jennynola@hotmail.com | P4: CWA of Victoria Inc | Q4: 3 | R4: 1 | S4: 2 | T4: 4 | U4: 2 | V4: 3 | W4: 1 | X4: 4 | Y4: 1 | Z4: 4 | AA4: 2 | AB4: 3 | AC4: 1 | AD4: 2 | AE4: 3 | AF4: 4 | AG4: 3 | AH4: 4 | AI4: 1 | AJ4: 2 | AK4: 1 | AL4: 3 | AM4: 2 | AN4: 4 | AO4: 2 | AP4: 3 | AQ4: 4 | AR4: 1 | AS4: 1 | AT4: 3 | AU4: 2 | AV4: 4 | AW4: 1 | AX4: 4 | AY4: 3 | AZ4: 2 | BA4: 1 | BB4: 3 | BC4: 2 | BD4: 4 | BE4: 1 | BF4: 2 | BG4: 4 | BH4: 3 | BI4: 2 | BJ4: 4 | BK4: 1 | BL4: 3
A5: 119146084654 | B5: 46193.369 | C5: 46193.375 | D5: 115.70.50.162 | E5: 504 | F5: completed | G5: Not Answered | H5: Not Answered | I5: Not Answered | J5: 464641143 | K5: weblink | L5: Not Answered | M5: Jacqui | N5: Kernot | O5: JACQUI.KERNOT@GMAIL.COM | P5: Model security | Q5: 2 | R5: 1 | S5: 3 | T5: 4 | U5: 2 | V5: 4 | W5: 1 | X5: 3 | Y5: 2 | Z5: 4 | AA5: 1 | AB5: 3 | AC5: 2 | AD5: 1 | AE5: 4 | AF5: 3 | AG5: 4 | AH5: 3 | AI5: 1 | AJ5: 2 | AK5: 3 | AL5: 2 | AM5: 1 | AN5: 4 | AO5: 1 | AP5: 3 | AQ5: 4 | AR5: 2 | AS5: 2 | AT5: 1 | AU5: 3 | AV5: 4 | AW5: 2 | AX5: 4 | AY5: 3 | AZ5: 1 | BA5: 1 | BB5: 4 | BC5: 2 | BD5: 3 | BE5: 1 | BF5: 2 | BG5: 4 | BH5: 3 | BI5: 4 | BJ5: 3 | BK5: 1 | BL5: 2
A6: 119155726248 | B6: 46209.04 | C6: 46209.049 | D6: 108.147.10.57 | E6: 843 | F6: completed | G6: Not Answered | H6: Not Answered | I6: Not Answered | J6: 464641143 | K6: weblink | L6: Not Answered | M6: Erikka | N6: Buracchio | O6: eaburacchio@gmail.com | P6: Retired | Q6: 3 | R6: 2 | S6: 1 | T6: 4 | U6: 3 | V6: 1 | W6: 4 | X6: 2 | Y6: 1 | Z6: 2 | AA6: 3 | AB6: 4 | AC6: 3 | AD6: 1 | AE6: 2 | AF6: 4 | AG6: 1 | AH6: 3 | AI6: 4 | AJ6: 2 | AK6: 4 | AL6: 1 | AM6: 2 | AN6: 3 | AO6: 1 | AP6: 3 | AQ6: 4 | AR6: 2 | AS6: 1 | AT6: 2 | AU6: 4 | AV6: 3 | AW6: 4 | AX6: 2 | AY6: 3 | AZ6: 1 | BA6: 1 | BB6: 3 | BC6: 2 | BD6: 4 | BE6: 2 | BF6: 1 | BG6: 3 | BH6: 4 | BI6: 2 | BJ6: 4 | BK6: 1 | BL6: 3
A7: 119155944476 | B7: 46209.591 | C7: 46209.605 | D7: 1.140.109.68 | E7: 1175 | F7: completed | G7: Not Answered | H7: Not Answered | I7: Not Answered | J7: 464641143 | K7: weblink | L7: Not Answered | M7: Jill | N7: Shapiro | O7: jillshapiro23@gmail.com | P7: AltX Financial Group | Q7: 3 | R7: 4 | S7: 2 | T7: 1 | U7: 3 | V7: 1 | W7: 2 | X7: 4 | Y7: 2 | Z7: 1 | AA7: 3 | AB7: 4 | AC7: 1 | AD7: 2 | AE7: 3 | AF7: 4 | AG7: 4 | AH7: 1 | AI7: 2 | AJ7: 3 | AK7: 2 | AL7: 3 | AM7: 1 | AN7: 4 | AO7: 2 | AP7: 1 | AQ7: 3 | AR7: 4 | AS7: 4 | AT7: 1 | AU7: 3 | AV7: 2 | AW7: 4 | AX7: 3 | AY7: 1 | AZ7: 2 | BA7: 3 | BB7: 1 | BC7: 2 | BD7: 4 | BE7: 3 | BF7: 1 | BG7: 2 | BH7: 4 | BI7: 2 | BJ7: 3 | BK7: 1 | BL7: 4

Sheet Epitome Archetype Framework 202
A1: Response ID | B1: Date Created | C1: Date Modified | D1: IP Address | E1: Duration (sec) | F1: Response Status | G1: Email | H1: First Name | I1: Last Name | J1: Collector ID | K1: Collector Type | L1: Custom Value | M1: Name | First name | N1: Name | Last name | O1: Email address | Email address | P1: Organization | Q1: What do you draw on to lead your team to deliver the optimum results? | Determination, charisma, and an innate understanding of the organization’s power structures | R1: What do you draw on to lead your team to deliver the optimum results? | An inspiring passion and intuitive understanding of individual and team dynamics | S1: What do you draw on to lead your team to deliver the optimum results? | The wisdom of my experience and an understanding of team dynamic | T1: What do you draw on to lead your team to deliver the optimum results? | The ability to amplify the reach of my boss and provide the behind the scenes insights | U1: What do you most trust when making decisions? | Information, evidence, and the informed insights from others that I trust | V1: What do you most trust when making decisions? | My instinct and gut in making sense of data and evidence and collaborating with others to assist me | W1: What do you most trust when making decisions? | My ability to understand the implications of information and which stakeholders need to be included in the decision-making process | X1: What do you most trust when making decisions? | My network’s strategic knowledge and my innate understanding of what they need to get the job done | Y1: What constrains me in work situations? | Chaos where the ultimate decision makers are not willing to make clear, tough decisions | Z1: What constrains me in work situations? | Lack of access to corporate knowledge and being sidelined from the decision-making process | AA1: What constrains me in work situations? | Over-reliance on cold, hard facts with little nuanced understanding of the people impact | AB1: What constrains me in work situations? | Lack of opportunity and an inability to have a visible and powerful impact | AC1: What inspires me in a senior leader? | An inspirational and passionate big picture thinker who understands the power of the team to realise significant objectives | AD1: What inspires me in a senior leader? | A compelling and strategic thinker who galvanises the team to execute with precision | AE1: What inspires me in a senior leader? | One that has a clear and captivating vision and recognizes and relies on my talents to execute on their strategy | AF1: What inspires me in a senior leader? | One that is powerful and has a magnetic vision and recognizes and celebrates my talent and ambition in driving results | AG1: As a leader, how do you deal with challenges and setbacks? | I rally the team to tackle the challenge and work together to ensure our success through innovative execution | AH1: As a leader, how do you deal with challenges and setbacks? | I figure out the key concerns that the leader has and work to address these to ensure a successful outcome | AI1: As a leader, how do you deal with challenges and setbacks? | I clarify the reasons for the challenge, bolster the team where necessary, and double down on execution to ensure my success | AJ1: As a leader, how do you deal with challenges and setbacks? | I focus on understanding the cause and systematically mitigate the challenge to set us up for success | AK1: How do work colleagues describe you? | As an influential, power behind the scenes and connected leader | AL1: How do work colleagues describe you? | As a passionate, inspiring and intuitive leader | AM1: How do work colleagues describe you? | As a wise, calm, and natural leader | AN1: How do work colleagues describe you? | As a charismatic, driven, and determined leader | AO1: What do you strive for in your role? | To build high performing teams that drive systemic, evidence-based, impactful outcomes | AP1: What do you strive for in your role? | To achieve the best outcome for my boss which bolster the organization’s strategy and benefits its people | AQ1: What do you strive for in your role? | To be the best by using my ambition and talent to achieve strategic corporate goals | AR1: What do you strive for in your role? | To bring together outstanding tight-knit teams with healthy cultures to deliver innovative, impactful results | AS1: How do you behave when working with your peers? | I lead with passion, an inspiring narrative, and galvanize the team through a deep intuitive understanding of individual and team dynamics | AT1: How do you behave when working with your peers? | I lead with analytic clarity, experiential wisdom, and a deep awareness of the team dynamic and how to harness this | AU1: How do you behave when working with your peers? | I lead with charisma, the ability to influence and shape the team, and a single-minded determination to deliver | AV1: How do you behave when working with your peers? | I lead by presenting the objectives of the organization and the goals of my boss and engage the team to ensure execution is the focus | AW1: How would you describe yourself at your worst (under pressure / bored / unhappy)? | Manipulative, political, demanding, icy, envious, furious, and a “win or die” attitude | AX1: How would you describe yourself at your worst (under pressure / bored / unhappy)? | Over-emotional, self-obsessed, easily enraged, scattered, cliquish, destructive, and hell-bent | AY1: How would you describe yourself at your worst (under pressure / bored / unhappy)? | Anxious, blinded by the loyalty to my boss, officious, dismissive, and passive aggressive | AZ1: How would you describe yourself at your worst (under pressure / bored / unhappy)? | Cold, disdainful, intimidating, unforgiving, and overly reliant on hard facts | BA1: What gives you confidence when acting in a leadership role? | The deep, intuitive understanding of what is at play, the creative and innovative capabilities I have, and my passion to make it happen | BB1: What gives you confidence when acting in a leadership role? | My self-belief and appreciation of my talent and a determination to be the very best at whatever I put my mind to | BC1: What gives you confidence when acting in a leadership role? | The belief in my capabilities, an understanding of the data, and a clear understanding of what needs to be achieved | BD1: What gives you confidence when acting in a leadership role? | The trust and belief that my leader has in me and my innate abilities to translate their vision into an exceptional performance
A2: 119046494047 | B2: 46051.749 | C2: 46051.756 | D2: 60.227.233.141 | E2: 633 | F2: completed | G2: Not Answered | H2: Not Answered | I2: Not Answered | J2: 462890650 | K2: weblink | L2: Not Answered | M2: Jessica | N2: Salvato | O2: jess@rela.com.au | P2: RELA | Q2: 2 | R2: 3 | S2: 1 | T2: 4 | U2: 1 | V2: 3 | W2: 2 | X2: 4 | Y2: 1 | Z2: 3 | AA2: 2 | AB2: 4 | AC2: 3 | AD2: 2 | AE2: 1 | AF2: 4 | AG2: 4 | AH2: 3 | AI2: 2 | AJ2: 1 | AK2: 1 | AL2: 4 | AM2: 3 | AN2: 2 | AO2: 2 | AP2: 4 | AQ2: 1 | AR2: 3 | AS2: 4 | AT2: 1 | AU2: 3 | AV2: 2 | AW2: 2 | AX2: 4 | AY2: 3 | AZ2: 1 | BA2: 3 | BB2: 2 | BC2: 1 | BD2: 4
A3: 119074346185 | B3: 46092.532 | C3: 46092.54 | D3: 98.171.54.241 | E3: 710 | F3: completed | G3: Not Answered | H3: Not Answered | I3: Not Answered | J3: 462890650 | K3: weblink | L3: Not Answered | M3: Allison | N3: Paul | O3: allisonpaul1313@gmail.com | P3: N/A | Q3: 2 | R3: 1 | S3: 3 | T3: 4 | U3: 1 | V3: 2 | W3: 3 | X3: 4 | Y3: 1 | Z3: 2 | AA3: 3 | AB3: 4 | AC3: 2 | AD3: 1 | AE3: 3 | AF3: 4 | AG3: 3 | AH3: 4 | AI3: 1 | AJ3: 2 | AK3: 4 | AL3: 2 | AM3: 3 | AN3: 1 | AO3: 2 | AP3: 4 | AQ3: 3 | AR3: 1 | AS3: 1 | AT3: 3 | AU3: 2 | AV3: 4 | AW3: 1 | AX3: 4 | AY3: 3 | AZ3: 2 | BA3: 1 | BB3: 3 | BC3: 2 | BD3: 4
A4: 119099699143 | B4: 46127.865 | C4: 46127.873 | D4: 119.18.0.183 | E4: 737 | F4: completed | G4: Not Answered | H4: Not Answered | I4: Not Answered | J4: 462890650 | K4: weblink | L4: Not Answered | M4: Jo-Anne | N4: Baker | O4: joabaker@icloud.com | P4: Healthiness | Q4: 4 | R4: 1 | S4: 2 | T4: 3 | U4: 2 | V4: 1 | W4: 4 | X4: 3 | Y4: 1 | Z4: 4 | AA4: 2 | AB4: 3 | AC4: 1 | AD4: 2 | AE4: 4 | AF4: 3 | AG4: 3 | AH4: 4 | AI4: 2 | AJ4: 1 | AK4: 4 | AL4: 2 | AM4: 1 | AN4: 3 | AO4: 2 | AP4: 3 | AQ4: 4 | AR4: 1 | AS4: 3 | AT4: 2 | AU4: 4 | AV4: 1 | AW4: 4 | AX4: 1 | AY4: 3 | AZ4: 2 | BA4: 3 | BB4: 1 | BC4: 2 | BD4: 4
A5: 119111838226 | B5: 46146.623 | C5: 46146.635 | D5: 111.220.62.16 | E5: 1116 | F5: completed | G5: Not Answered | H5: Not Answered | I5: Not Answered | J5: 462890650 | K5: weblink | L5: Not Answered | M5: Kelly | N5: Slater | O5: kelly@theslaters.com.au | P5: Kelly Slater Business Consulting | Q5: 4 | R5: 3 | S5: 1 | T5: 2 | U5: 3 | V5: 1 | W5: 2 | X5: 4 | Y5: 1 | Z5: 4 | AA5: 3 | AB5: 2 | AC5: 2 | AD5: 1 | AE5: 3 | AF5: 4 | AG5: 2 | AH5: 3 | AI5: 4 | AJ5: 1 | AK5: 1 | AL5: 2 | AM5: 3 | AN5: 4 | AO5: 1 | AP5: 2 | AQ5: 4 | AR5: 3 | AS5: 4 | AT5: 3 | AU5: 2 | AV5: 1 | AW5: 4 | AX5: 2 | AY5: 1 | AZ5: 3 | BA5: 4 | BB5: 2 | BC5: 1 | BD5: 3
A6: 119111879758 | B6: 46146.739 | C6: 46146.74 | D6: 180.150.112.172 | E6: 146 | F6: partial | G6: Not Answered | H6: Not Answered | I6: Not Answered | J6: 462890650 | K6: weblink | L6: Not Answered | M6: Rebecca | N6: Blumberg | O6: rebeccaverablumberg@gmail.com | P6: Office of the Director of Public Prosecutions | Q6: 3 | R6: 2 | S6: 1 | T6: 4 | U6: Not Answered | V6: Not Answered | W6: Not Answered | X6: Not Answered | Y6: Not Answered | Z6: Not Answered | AA6: Not Answered | AB6: Not Answered | AC6: Not Answered | AD6: Not Answered | AE6: Not Answered | AF6: Not Answered | AG6: Not Answered | AH6: Not Answered | AI6: Not Answered | AJ6: Not Answered | AK6: Not Answered | AL6: Not Answered | AM6: Not Answered | AN6: Not Answered | AO6: Not Answered | AP6: Not Answered | AQ6: Not Answered | AR6: Not Answered | AS6: Not Answered | AT6: Not Answered | AU6: Not Answered | AV6: Not Answered | AW6: Not Answered | AX6: Not Answered | AY6: Not Answered | AZ6: Not Answered | BA6: Not Answered | BB6: Not Answered | BC6: Not Answered | BD6: Not Answered
A7: 119116046215 | B7: 46152.546 | C7: 46152.551 | D7: 180.150.112.172 | E7: 388 | F7: completed | G7: Not Answered | H7: Not Answered | I7: Not Answered | J7: 462890650 | K7: weblink | L7: Not Answered | M7: Rebecca | N7: Blumberg | O7: rebeccaverablumberg@gmail.com | P7: South Australian Director of Public Prosecutions | Q7: 3 | R7: 1 | S7: 2 | T7: 4 | U7: 2 | V7: 1 | W7: 4 | X7: 3 | Y7: 3 | Z7: 2 | AA7: 4 | AB7: 1 | AC7: 2 | AD7: 4 | AE7: 3 | AF7: 1 | AG7: 1 | AH7: 4 | AI7: 2 | AJ7: 3 | AK7: 4 | AL7: 2 | AM7: 3 | AN7: 1 | AO7: 3 | AP7: 4 | AQ7: 2 | AR7: 1 | AS7: 1 | AT7: 3 | AU7: 2 | AV7: 4 | AW7: 3 | AX7: 1 | AY7: 2 | AZ7: 4 | BA7: 3 | BB7: 1 | BC7: 2 | BD7: 4
A8: 119116112761 | B8: 46152.794 | C8: 46152.804 | D8: 60.226.135.180 | E8: 828 | F8: completed | G8: Not Answered | H8: Not Answered | I8: Not Answered | J8: 462890650 | K8: weblink | L8: Not Answered | M8: Lana | N8: Johnston | O8: lanajj24@outlook.com | P8: Taking It Forward | Q8: 3 | R8: 2 | S8: 1 | T8: 4 | U8: 3 | V8: 2 | W8: 1 | X8: 4 | Y8: 3 | Z8: 2 | AA8: 4 | AB8: 1 | AC8: 1 | AD8: 2 | AE8: 3 | AF8: 4 | AG8: 1 | AH8: 2 | AI8: 4 | AJ8: 3 | AK8: 2 | AL8: 3 | AM8: 1 | AN8: 4 | AO8: 2 | AP8: 3 | AQ8: 4 | AR8: 1 | AS8: 1 | AT8: 2 | AU8: 3 | AV8: 4 | AW8: 2 | AX8: 1 | AY8: 4 | AZ8: 3 | BA8: 1 | BB8: 2 | BC8: 3 | BD8: 4

Sheet Reference
B1: 1 | C1: 1 | D1: 1 | E1: 1 | F1: 2 | G1: 2 | H1: 2 | I1: 2 | J1: 3 | K1: 3 | L1: 3 | M1: 3 | N1: 4 | O1: 4 | P1: 4 | Q1: 4 | R1: 5 | S1: 5 | T1: 5 | U1: 5 | V1: 6 | W1: 6 | X1: 6 | Y1: 6 | Z1: 7 | AA1: 7 | AB1: 7 | AC1: 7 | AD1: 8 | AE1: 8 | AF1: 8 | AG1: 8 | AH1: 9 | AI1: 9 | AJ1: 9 | AK1: 9 | AL1: 10 | AM1: 10 | AN1: 10 | AO1: 10 | AP1: 11 | AQ1: 11 | AR1: 11 | AS1: 11 | AT1: 12 | AU1: 12 | AV1: 12 | AW1: 12
B2: Sovereign | C2: Empress | D2: Consort | E2: Seductress | F2: Sovereign | G2: Empress | H2: Consort | I2: Seductress | J2: Sovereign | K2: Empress | L2: Consort | M2: Seductress | N2: Sovereign | O2: Empress | P2: Consort | Q2: Seductress | R2: Sovereign | S2: Empress | T2: Consort | U2: Seductress | V2: Sovereign | W2: Empress | X2: Consort | Y2: Seductress | Z2: Sovereign | AA2: Empress | AB2: Consort | AC2: Seductress | AD2: Sovereign | AE2: Empress | AF2: Consort | AG2: Seductress | AH2: Sovereign | AI2: Empress | AJ2: Consort | AK2: Seductress | AL2: Sovereign | AM2: Empress | AN2: Consort | AO2: Seductress | AP2: Sovereign | AQ2: Empress | AR2: Consort | AS2: Seductress | AT2: Sovereign | AU2: Empress | AV2: Consort | AW2: Seductress
B3: What do you draw on to lead your team to deliver the optimum results? | The wisdom of my experience and an understanding of team dynamic | C3: What do you draw on to lead your team to deliver the optimum results? | An inspiring passion and intuitive understanding of individual and team dynamics | D3: What do you draw on to lead your team to deliver the optimum results? | The ability to amplify the reach of my boss and provide the behind the scenes insights | E3: What do you draw on to lead your team to deliver the optimum results? | Determination, charisma, and an innate understanding of the organization’s power structures | F3: What do you most trust when making decisions? | Information, evidence, and the informed insights from others that I trust | G3: What do you most trust when making decisions? | My instinct and gut in making sense of data and evidence and collaborating with others to assist me | H3: What do you most trust when making decisions? | My network’s strategic knowledge and my innate understanding of what they need to get the job done | I3: What do you most trust when making decisions? | My ability to understand the implications of information and which stakeholders need to be included in the decision-making process | J3: What constrains me in work situations? | Chaos where the ultimate decision makers are not willing to make clear, tough decisions | K3: What constrains me in work situations? | Over-reliance on cold, hard facts with little nuanced understanding of the people impact | L3: What constrains me in work situations? | Lack of access to corporate knowledge and being sidelined from the decision-making process | M3: What constrains me in work situations? | Lack of opportunity and an inability to have a visible and powerful impact | N3: What inspires me in a senior leader? | A compelling and strategic thinker who galvanises the team to execute with precision | O3: What inspires me in a senior leader? | An inspirational and passionate big picture thinker who understands the power of the team to realise significant objectives | P3: What inspires me in a senior leader? | One that has a clear and captivating vision and recognizes and relies on my talents to execute on their strategy | Q3: What inspires me in a senior leader? | One that is powerful and has a magnetic vision and recognizes and celebrates my talent and ambition in driving results | R3: As a leader, how do you manage challenges and setbacks? | I clarify the reasons for the challenge, bolster the team where necessary, and double down on execution to ensure my success | S3: As a leader, how do you manage challenges and setbacks? | I rally the team to tackle the challenge and work together to ensure our success through innovative execution | T3: As a leader, how do you manage challenges and setbacks? | I figure out the key concerns that the leader has and work to address these to ensure a successful outcome | U3: As a leader, how do you manage challenges and setbacks? | I clarify the reasons for the challenge, bolster the team where necessary, and double down on execution to ensure my success | V3: How do colleagues describe you? | As a wise, calm, and natural leader | W3: How do colleagues describe you? | As a passionate, inspiring and intuitive leader | X3: How do colleagues describe you? | As an influential, power behind the scenes and connected leader | Y3: How do colleagues describe you? | As a charismatic, driven, and determined leader | Z3: What do you strive for in your role? | To build high performing teams that drive systemic, evidence-based, impactful outcomes | AA3: What do you strive for in your role? | To bring together outstanding tight-knit teams with healthy cultures to deliver innovative, impactful results | AB3: What do you strive for in your role? | To achieve the best outcome for my leader which bolster the organization’s strategy and benefit its people | AC3: What do you strive for in your role? | To be the best by using my ambition and talent to achieve strategic corporate goals | AD3: How do you behave when working with your peers? | I lead with analytic clarity, experiential wisdom, and a deep awareness of the team dynamic | AE3: How do you behave when working with your peers? | I lead with passion, an inspiring narrative, and a deep intuitive understanding of the individual and team dynamics | AF3: How do you behave when working with your peers? | I lead by presenting the objectives and goals of the leader, and a focus on the outstanding execution of these | AG3: How do you behave when working with your peers? | I lead with charisma, the ability to shape the team, and a single-minded determination to deliver | AH3: How would you describe yourself at your worst (under pressure / bored /unhappy)? | Cold, disdainful, intimidating, unforgiving, and overly reliant on hard facts | AI3: How would you describe yourself at your worst (under pressure / bored /unhappy)? | Over-emotional, self-obsessed, easily enraged, scattered, cliquish, destructive, and hell-bent | AJ3: How would you describe yourself at your worst (under pressure / bored /unhappy)? | Anxious, blinded by the loyalty to the leader, officious, dismissive, and passive aggressive | AK3: How would you describe yourself at your worst (under pressure / bored /unhappy)? | Manipulative, political, demanding, icy, envious, furious, and a “win or die” attitude | AL3: What gives you confidence when acting in a leadership role? | The belief in my capabilities, an understanding of the data, and a clear understanding of what needs to be achieved | AM3: What gives you confidence when acting in a leadership role? | The deep, intuitive understanding of what is at play, the creative and innovative capabilities I have, and my passion to make it happen | AN3: What gives you confidence when acting in a leadership role? | The trust and belief that my leader has in me and my innate abilities to translate their vision into an exceptional performance | AO3: What gives you confidence when acting in a leadership role? | My self-belief and appreciation of my talent and a determination to be the very best at whatever I put my mind to. | AP3: How do you relate to power in your leadership role? | I hold power with quiet authority. I know I have it, I do not need to demonstrate it, and I use it to create clarity and direction for those around me | AQ3: How do you relate to power in your leadership role? | My power lives in my people. I am genuinely most powerful in a collective, and I build teams that are greater than the sum of their parts | AR3: How do you relate to power in your leadership role? | My power is relational, it flows from my deep understanding of my leader and organisation, and I am most effective when that relationship is strong and trusted | AS3: How do you relate to power in your leadership role? | I understand power instinctively - where it sits, how it moves, and how to position myself within it to achieve what I am here to achieve | AT3: How would you describe your relationship with ambition? | I am ambitious for outcomes and legacy. I believe in stewardship and want to build something that outlasts me. I hold a long view of what success looks like | AU3: How would you describe your relationship with ambition? | My ambition is for the collective. I want to build teams and cultures where people genuinely thrive, and that matters to me as much as any metric | AV3: How would you describe your relationship with ambition? | My ambition is channelled through my commitment to my leader and the organisation. I measure success by the quality and success of what we achieve together | AW3: How would you describe your relationship with ambition? | I am unambiguously ambitious - for impact, for recognition, for being at the centre of what matters, and for making an impact. And I make no apology for that
B4: S | C4: R | D4: T | E4: Q | F4: U | G4: V | H4: X | I4: W | J4: Y | K4: AA | L4: Z | M4: AB | N4: AD | O4: AC | P4: AE | Q4: AF | R4: AJ | S4: AG | T4: AH | U4: AI | V4: AM | W4: AL | X4: AK | Y4: AN | Z4: AO | AA4: AR | AB4: AP | AC4: AQ | AD4: AT | AE4: AS | AF4: AV | AG4: AU | AH4: AZ | AI4: AX | AJ4: AY | AK4: AW | AL4: BC | AM4: BA | AN4: BD | AO4: BB | AP4: BF | AQ4: BE | AR4: BG | AS4: BH | AT4: BL | AU4: BK | AV4: BI | AW4: BJ
B5: 19 | C5: 18 | D5: 20 | E5: 17 | F5: 21 | G5: 22 | H5: 24 | I5: 23 | J5: 25 | K5: 27 | L5: 26 | M5: 28 | N5: 30 | O5: 29 | P5: 31 | Q5: 32 | R5: 36 | S5: 33 | T5: 34 | U5: 35 | V5: 39 | W5: 38 | X5: 37 | Y5: 40 | Z5: 41 | AA5: 44 | AB5: 42 | AC5: 43 | AD5: 46 | AE5: 45 | AF5: 48 | AG5: 47 | AH5: 52 | AI5: 50 | AJ5: 51 | AK5: 49 | AL5: 55 | AM5: 53 | AN5: 56 | AO5: 54 | AP5: 58 | AQ5: 57 | AR5: 59 | AS5: 60 | AT5: 64 | AU5: 63 | AV5: 61 | AW5: 62
B6: =A10 -> Leading | C6: =A10 -> Leading | D6: =A10 -> Leading | E6: =A10 -> Leading | F6: =$A$11 -> Trust | G6: =$A$11 -> Trust | H6: =$A$11 -> Trust | I6: =$A$11 -> Trust | J6: =$A$12 -> Constraints | K6: =$A$12 -> Constraints | L6: =$A$12 -> Constraints | M6: =$A$12 -> Constraints | N6: =A13 -> Inspiration | O6: =A13 -> Inspiration | P6: =A13 -> Inspiration | Q6: =A13 -> Inspiration | R6: =A14 -> Managing Challenges | S6: =A14 -> Managing Challenges | T6: =A14 -> Managing Challenges | U6: =A14 -> Managing Challenges | V6: =A15 -> Others View Me | W6: =A15 -> Others View Me | X6: =A15 -> Others View Me | Y6: =A15 -> Others View Me | Z6: =A16 -> Striving | AA6: =A16 -> Striving | AB6: =A16 -> Striving | AC6: =A16 -> Striving | AD6: =A17 -> Working With Peers | AE6: =A17 -> Working With Peers | AF6: =A17 -> Working With Peers | AG6: =A17 -> Working With Peers | AH6: =A18 -> At Your Worst | AI6: =A18 -> At Your Worst | AJ6: =A18 -> At Your Worst | AK6: =A18 -> At Your Worst | AL6: =A19 -> Confidence | AM6: =A19 -> Confidence | AN6: =A19 -> Confidence | AO6: =A19 -> Confidence | AP6: =A20 -> Power | AQ6: =A20 -> Power | AR6: =A20 -> Power | AS6: =A20 -> Power | AT6: =A21 -> Ambition | AU6: =A21 -> Ambition | AV6: =A21 -> Ambition | AW6: =A21 -> Ambition
B7: =A24 -> Sovereign | C7: =A25 -> Empress | D7: =A26 -> Consort | E7: =A27 -> Seductress | F7: =A24 -> Sovereign | G7: =A25 -> Empress | H7: =A26 -> Consort | I7: =A27 -> Seductress | J7: =A24 -> Sovereign | K7: =A25 -> Empress | L7: =A26 -> Consort | M7: =A27 -> Seductress | N7: =A24 -> Sovereign | O7: =A25 -> Empress | P7: =A26 -> Consort | Q7: =A27 -> Seductress | R7: =A24 -> Sovereign | S7: =A25 -> Empress | T7: =A26 -> Consort | U7: =A27 -> Seductress | V7: =A24 -> Sovereign | W7: =A25 -> Empress | X7: =A26 -> Consort | Y7: =A27 -> Seductress | Z7: =A24 -> Sovereign | AA7: =A25 -> Empress | AB7: =A26 -> Consort | AC7: =A27 -> Seductress | AD7: =A24 -> Sovereign | AE7: =A25 -> Empress | AF7: =A26 -> Consort | AG7: =A27 -> Seductress | AH7: =A24 -> Sovereign | AI7: =A25 -> Empress | AJ7: =A26 -> Consort | AK7: =A27 -> Seductress | AL7: =A24 -> Sovereign | AM7: =A25 -> Empress | AN7: =A26 -> Consort | AO7: =A27 -> Seductress | AP7: =A24 -> Sovereign | AQ7: =A25 -> Empress | AR7: =A26 -> Consort | AS7: =A27 -> Seductress | AT7: =A24 -> Sovereign | AU7: =A25 -> Empress | AV7: =A26 -> Consort | AW7: =A27 -> Seductress
A9: Topics
A10: Leading | B10: At best
A11: Trust | B11: At best
A12: Constraints | B12: At worst
A13: Inspiration | B13: At best
A14: Managing Challenges | B14: At best
A15: Others View Me | B15: At best
A16: Striving | B16: At best
A17: Working With Peers | B17: At best
A18: At Your Worst | B18: At worst
A19: Confidence | B19: At best
A20: Power | B20: At best
A21: Ambition | B21: At best
A23: Archetypes
A24: Sovereign
A25: Empress
A26: Consort
A27: Seductress

Sheet Analysis
A1: Response | B1: Name | C1: Surname | D1: Organization | E1: Sovereign | F1: Empress | G1: Consort | H1: Seductress | I1: Dominant Archetype | J1: Dominant Archetype | K1: Dominant Archetype | L1: Dominant Archetype | M1: Notes
A2: Response 1 | B2: ='Epitome Archetype Guide'!$M2 -> Laura | C2: ='Epitome Archetype Guide'!$N2 -> Taitz | D2: ='Epitome Archetype Guide'!$P2 -> Fraction PM | E2: ='Response 1'!N5 -> 30 | F2: ='Response 1'!N6 -> 23 | G2: ='Response 1'!N7 -> 33 | H2: ='Response 1'!N8 -> 34 | I2: =IF(SUM(E2:H2)<>0,IF(E2=MIN($E2:$H2), E$1, "")) | J2: =IF(SUM(E2:H2)<>0,IF(F2=MIN($E2:$H2), F$1, "")) -> Empress | K2: =IF(SUM(E2:H2)<>0,IF(G2=MIN($E2:$H2), G$1, "")) | L2: =IF(SUM(E2:H2)<>0,IF(H2=MIN($E2:$H2), H$1, ""))
A3: Response 2 | B3: ='Epitome Archetype Guide'!$M3 -> Merle | C3: ='Epitome Archetype Guide'!$N3 -> Singer | D3: ='Epitome Archetype Guide'!$P3 -> Epitome Leadership | E3: =' Response 2'!N5 -> 23 | F3: =' Response 2'!N6 -> 18 | G3: =' Response 2'!N7 -> 29 | H3: =' Response 2'!N8 -> 30 | I3: =IF(SUM(E3:H3)<>0,IF(E3=MIN($E3:$H3), E$1, "")) | J3: =IF(SUM(E3:H3)<>0,IF(F3=MIN($E3:$H3), F$1, "")) -> Empress | K3: =(IF(G3=MIN($E3:$H3), G$1, "")) | L3: =(IF(H3=MIN($E3:$H3), H$1, ""))
A4: Response 3 | B4: ='Epitome Archetype Guide'!$M4 -> Jenny | C4: ='Epitome Archetype Guide'!$N4 -> Nola | D4: ='Epitome Archetype Guide'!$P4 -> CWA of Victoria Inc | E4: ='Response 3'!N5 -> 20 | F4: ='Response 3'!N6 -> 20 | G4: ='Response 3'!N7 -> 34 | H4: ='Response 3'!N8 -> 26 | I4: =IF(SUM(E4:H4)<>0,IF(E4=MIN($E4:$H4), E$1, "")) -> Sovereign | J4: =IF(SUM(E4:H4)<>0,IF(F4=MIN($E4:$H4), F$1, "")) -> Empress | K4: =IF(SUM(E4:H4)<>0,IF(G4=MIN($E4:$H4), G$1, "")) | L4: =IF(SUM(E4:H4)<>0,IF(H4=MIN($E4:$H4), H$1, ""))
A5: Response 4 | B5: ='Epitome Archetype Guide'!$M5 -> Jacqui | C5: ='Epitome Archetype Guide'!$N5 -> Kernot | D5: ='Epitome Archetype Guide'!$P5 -> Model security | E5: ='Response 4'!N5 -> 16 | F5: ='Response 4'!N6 -> 23 | G5: ='Response 4'!N7 -> 34 | H5: ='Response 4'!N8 -> 27 | I5: =IF(SUM(E5:H5)<>0,IF(E5=MIN($E5:$H5), E$1, "")) -> Sovereign | J5: =IF(SUM(E5:H5)<>0,IF(F5=MIN($E5:$H5), F$1, "")) | K5: =IF(SUM(E5:H5)<>0,IF(G5=MIN($E5:$H5), G$1, "")) | L5: =IF(SUM(E5:H5)<>0,IF(H5=MIN($E5:$H5), H$1, ""))
A6: Response 5 | B6: ='Epitome Archetype Guide'!$M6 -> Erikka | C6: ='Epitome Archetype Guide'!$N6 -> Buracchio | D6: ='Epitome Archetype Guide'!$P6 -> Retired | E6: ='Response 5'!N5 -> 16 | F6: ='Response 5'!N6 -> 17 | G6: ='Response 5'!N7 -> 30 | H6: ='Response 5'!N8 -> 37 | I6: =IF(SUM(E6:H6)<>0,IF(E6=MIN($E6:$H6), E$1, "")) -> Sovereign | J6: =IF(SUM(E6:H6)<>0,IF(F6=MIN($E6:$H6), F$1, "")) | K6: =IF(SUM(E6:H6)<>0,IF(G6=MIN($E6:$H6), G$1, "")) | L6: =IF(SUM(E6:H6)<>0,IF(H6=MIN($E6:$H6), H$1, ""))
A7: Response 6 | B7: ='Epitome Archetype Guide'!$M7 -> Jill | C7: ='Epitome Archetype Guide'!$N7 -> Shapiro | D7: ='Epitome Archetype Guide'!$P7 -> AltX Financial Group | E7: ='Response 6'!N5 -> 20 | F7: ='Response 6'!N6 -> 30 | G7: ='Response 6'!N7 -> 20 | H7: ='Response 6'!N8 -> 30 | I7: =IF(SUM(E7:H7)<>0,IF(E7=MIN($E7:$H7), E$1, "")) -> Sovereign | J7: =IF(SUM(E7:H7)<>0,IF(F7=MIN($E7:$H7), F$1, "")) | K7: =IF(SUM(E7:H7)<>0,IF(G7=MIN($E7:$H7), G$1, "")) -> Consort | L7: =IF(SUM(E7:H7)<>0,IF(H7=MIN($E7:$H7), H$1, ""))
A8: Response 7 | B8: ='Epitome Archetype Guide'!$M8 -> 0 | C8: ='Epitome Archetype Guide'!$N8 -> 0 | D8: ='Epitome Archetype Guide'!$P8 -> 0 | E8: ='Response 7'!N5 -> 0 | F8: ='Response 7'!N6 -> 0 | G8: ='Response 7'!N7 -> 0 | H8: ='Response 7'!N8 -> 0 | I8: =IF(SUM(E8:H8)<>0,IF(E8=MIN($E8:$H8), E$1, "")) -> FALSE | J8: =IF(SUM(E8:H8)<>0,IF(F8=MIN($E8:$H8), F$1, "")) -> FALSE | K8: =IF(SUM(E8:H8)<>0,IF(G8=MIN($E8:$H8), G$1, "")) -> FALSE | L8: =IF(SUM(E8:H8)<>0,IF(H8=MIN($E8:$H8), H$1, "")) -> FALSE
A9: Response 8 | B9: ='Epitome Archetype Guide'!$M9 -> 0 | C9: ='Epitome Archetype Guide'!$N9 -> 0 | D9: ='Epitome Archetype Guide'!$P9 -> 0 | E9: ='Response 8'!N5 -> 0 | F9: ='Response 8'!N6 -> 0 | G9: ='Response 8'!N7 -> 0 | H9: ='Response 8'!N8 -> 0 | I9: =IF(SUM(E9:H9)<>0,IF(E9=MIN($E9:$H9), E$1, "")) -> FALSE | J9: =IF(SUM(E9:H9)<>0,IF(F9=MIN($E9:$H9), F$1, "")) -> FALSE | K9: =IF(SUM(E9:H9)<>0,IF(G9=MIN($E9:$H9), G$1, "")) -> FALSE | L9: =IF(SUM(E9:H9)<>0,IF(H9=MIN($E9:$H9), H$1, "")) -> FALSE
A10: Response 9 | B10: ='Epitome Archetype Guide'!$M10 -> 0 | C10: ='Epitome Archetype Guide'!$N10 -> 0 | D10: ='Epitome Archetype Guide'!$P10 -> 0 | E10: ='Response 9'!N5 -> 0 | F10: ='Response 9'!N6 -> 0 | G10: ='Response 9'!N7 -> 0 | H10: ='Response 9'!N8 -> 0 | I10: =IF(SUM(E10:H10)<>0,IF(E10=MIN($E10:$H10), E$1, "")) -> FALSE | J10: =IF(SUM(E10:H10)<>0,IF(F10=MIN($E10:$H10), F$1, "")) -> FALSE | K10: =IF(SUM(E10:H10)<>0,IF(G10=MIN($E10:$H10), G$1, "")) -> FALSE | L10: =IF(SUM(E10:H10)<>0,IF(H10=MIN($E10:$H10), H$1, "")) -> FALSE
A11: Response 10 | B11: ='Epitome Archetype Guide'!$M11 -> 0 | C11: ='Epitome Archetype Guide'!$N11 -> 0 | D11: ='Epitome Archetype Guide'!$P11 -> 0 | E11: ='Response 10'!N5 -> 0 | F11: ='Response 10'!N6 -> 0 | G11: ='Response 10'!N7 -> 0 | H11: ='Response 10'!N8 -> 0 | I11: =IF(SUM(E11:H11)<>0,IF(E11=MIN($E11:$H11), E$1, "")) -> FALSE | J11: =IF(SUM(E11:H11)<>0,IF(F11=MIN($E11:$H11), F$1, "")) -> FALSE | K11: =IF(SUM(E11:H11)<>0,IF(G11=MIN($E11:$H11), G$1, "")) -> FALSE | L11: =IF(SUM(E11:H11)<>0,IF(H11=MIN($E11:$H11), H$1, "")) -> FALSE
A12: Response 11 | B12: ='Epitome Archetype Guide'!$M12 -> 0 | C12: ='Epitome Archetype Guide'!$N12 -> 0 | D12: ='Epitome Archetype Guide'!$P12 -> 0 | E12: ='Response 11'!N5 -> 0 | F12: ='Response 11'!N6 -> 0 | G12: ='Response 11'!N7 -> 0 | H12: ='Response 11'!N8 -> 0 | I12: =IF(SUM(E12:H12)<>0,IF(E12=MIN($E12:$H12), E$1, "")) -> FALSE | J12: =IF(SUM(E12:H12)<>0,IF(F12=MIN($E12:$H12), F$1, "")) -> FALSE | K12: =IF(SUM(E12:H12)<>0,IF(G12=MIN($E12:$H12), G$1, "")) -> FALSE | L12: =IF(SUM(E12:H12)<>0,IF(H12=MIN($E12:$H12), H$1, "")) -> FALSE
A13: Response 12 | B13: ='Epitome Archetype Guide'!$M13 -> 0 | C13: ='Epitome Archetype Guide'!$N13 -> 0 | D13: ='Epitome Archetype Guide'!$P13 -> 0 | E13: ='Response 12'!N5 -> 0 | F13: ='Response 12'!N6 -> 0 | G13: ='Response 12'!N7 -> 0 | H13: ='Response 12'!N8 -> 0 | I13: =IF(SUM(E13:H13)<>0,IF(E13=MIN($E13:$H13), E$1, "")) -> FALSE | J13: =IF(SUM(E13:H13)<>0,IF(F13=MIN($E13:$H13), F$1, "")) -> FALSE | K13: =IF(SUM(E13:H13)<>0,IF(G13=MIN($E13:$H13), G$1, "")) -> FALSE | L13: =IF(SUM(E13:H13)<>0,IF(H13=MIN($E13:$H13), H$1, "")) -> FALSE
A14: Response 13 | B14: ='Epitome Archetype Guide'!$M14 -> 0 | C14: ='Epitome Archetype Guide'!$N14 -> 0 | D14: ='Epitome Archetype Guide'!$P14 -> 0 | E14: ='Response 13'!N6 -> 0 | F14: ='Response 13'!N6 -> 0 | G14: ='Response 13'!N7 -> 0 | H14: ='Response 13'!N8 -> 0 | I14: =IF(SUM(E14:H14)<>0,IF(E14=MIN($E14:$H14), E$1, "")) -> FALSE | J14: =IF(SUM(E14:H14)<>0,IF(F14=MIN($E14:$H14), F$1, "")) -> FALSE | K14: =IF(SUM(E14:H14)<>0,IF(G14=MIN($E14:$H14), G$1, "")) -> FALSE | L14: =IF(SUM(E14:H14)<>0,IF(H14=MIN($E14:$H14), H$1, "")) -> FALSE
A15: Response 14 | B15: ='Epitome Archetype Guide'!$M15 -> 0 | C15: ='Epitome Archetype Guide'!$N15 -> 0 | D15: ='Epitome Archetype Guide'!$P15 -> 0 | E15: ='Response 14'!N5 -> 0 | F15: ='Response 14'!N6 -> 0 | G15: ='Response 14'!N7 -> 0 | H15: ='Response 14'!N8 -> 0 | I15: =IF(SUM(E15:H15)<>0,IF(E15=MIN($E15:$H15), E$1, "")) -> FALSE | J15: =IF(SUM(E15:H15)<>0,IF(F15=MIN($E15:$H15), F$1, "")) -> FALSE | K15: =IF(SUM(E15:H15)<>0,IF(G15=MIN($E15:$H15), G$1, "")) -> FALSE | L15: =IF(SUM(E15:H15)<>0,IF(H15=MIN($E15:$H15), H$1, "")) -> FALSE
A16: Response 15 | B16: ='Epitome Archetype Guide'!$M16 -> 0 | C16: ='Epitome Archetype Guide'!$N16 -> 0 | D16: ='Epitome Archetype Guide'!$P16 -> 0 | E16: ='Response 15'!N5 -> 0 | F16: ='Response 15'!N6 -> 0 | G16: ='Response 15'!N7 -> 0 | H16: ='Response 15'!N8 -> 0 | I16: =IF(SUM(E16:H16)<>0,IF(E16=MIN($E16:$H16), E$1, "")) -> FALSE | J16: =IF(SUM(E16:H16)<>0,IF(F16=MIN($E16:$H16), F$1, "")) -> FALSE | K16: =IF(SUM(E16:H16)<>0,IF(G16=MIN($E16:$H16), G$1, "")) -> FALSE | L16: =IF(SUM(E16:H16)<>0,IF(H16=MIN($E16:$H16), H$1, "")) -> FALSE
A17: Response 16 | B17: ='Epitome Archetype Guide'!$M17 -> 0 | C17: ='Epitome Archetype Guide'!$N17 -> 0 | D17: ='Epitome Archetype Guide'!$P17 -> 0 | E17: ='Response 16'!N5 -> 0 | F17: ='Response 16'!N6 -> 0 | G17: ='Response 16'!N7 -> 0 | H17: ='Response 16'!N8 -> 0 | I17: =IF(SUM(E17:H17)<>0,IF(E17=MIN($E17:$H17), E$1, "")) -> FALSE | J17: =IF(SUM(E17:H17)<>0,IF(F17=MIN($E17:$H17), F$1, "")) -> FALSE | K17: =IF(SUM(E17:H17)<>0,IF(G17=MIN($E17:$H17), G$1, "")) -> FALSE | L17: =IF(SUM(E17:H17)<>0,IF(H17=MIN($E17:$H17), H$1, "")) -> FALSE
A18: Response 17 | B18: ='Epitome Archetype Guide'!$M18 -> 0 | C18: ='Epitome Archetype Guide'!$N18 -> 0 | D18: ='Epitome Archetype Guide'!$P18 -> 0 | E18: ='Response 17'!N5 -> 0 | F18: ='Response 17'!N6 -> 0 | G18: ='Response 17'!N7 -> 0 | H18: ='Response 17'!N8 -> 0 | I18: =IF(SUM(E18:H18)<>0,IF(E18=MIN($E18:$H18), E$1, "")) -> FALSE | J18: =IF(SUM(E18:H18)<>0,IF(F18=MIN($E18:$H18), F$1, "")) -> FALSE | K18: =IF(SUM(E18:H18)<>0,IF(G18=MIN($E18:$H18), G$1, "")) -> FALSE | L18: =IF(SUM(E18:H18)<>0,IF(H18=MIN($E18:$H18), H$1, "")) -> FALSE
A19: Response 18 | B19: ='Epitome Archetype Guide'!$M19 -> 0 | C19: ='Epitome Archetype Guide'!$N19 -> 0 | D19: ='Epitome Archetype Guide'!$P19 -> 0 | E19: ='Response 18'!N5 -> 0 | F19: ='Response 18'!N6 -> 0 | G19: ='Response 18'!N7 -> 0 | H19: ='Response 18'!N8 -> 0 | I19: =IF(SUM(E19:H19)<>0,IF(E19=MIN($E19:$H19), E$1, "")) -> FALSE | J19: =IF(SUM(E19:H19)<>0,IF(F19=MIN($E19:$H19), F$1, "")) -> FALSE | K19: =IF(SUM(E19:H19)<>0,IF(G19=MIN($E19:$H19), G$1, "")) -> FALSE | L19: =IF(SUM(E19:H19)<>0,IF(H19=MIN($E19:$H19), H$1, "")) -> FALSE
A20: Response 19 | B20: ='Epitome Archetype Guide'!$M20 -> 0 | C20: ='Epitome Archetype Guide'!$N20 -> 0 | D20: ='Epitome Archetype Guide'!$P20 -> 0 | E20: ='Response 19'!N5 -> 0 | F20: ='Response 19'!N6 -> 0 | G20: ='Response 19'!N7 -> 0 | H20: ='Response 19'!N8 -> 0 | I20: =IF(SUM(E20:H20)<>0,IF(E20=MIN($E20:$H20), E$1, "")) -> FALSE | J20: =IF(SUM(E20:H20)<>0,IF(F20=MIN($E20:$H20), F$1, "")) -> FALSE | K20: =IF(SUM(E20:H20)<>0,IF(G20=MIN($E20:$H20), G$1, "")) -> FALSE | L20: =IF(SUM(E20:H20)<>0,IF(H20=MIN($E20:$H20), H$1, "")) -> FALSE
A21: Response 20 | B21: ='Epitome Archetype Guide'!$M21 -> 0 | C21: ='Epitome Archetype Guide'!$N21 -> 0 | D21: ='Epitome Archetype Guide'!$P21 -> 0 | E21: ='Response 20'!N5 -> 0 | F21: ='Response 20'!N6 -> 0 | G21: ='Response 20'!N7 -> 0 | H21: ='Response 20'!N8 -> 0 | I21: =IF(SUM(E21:H21)<>0,IF(E21=MIN($E21:$H21), E$1, "")) -> FALSE | J21: =IF(SUM(E21:H21)<>0,IF(F21=MIN($E21:$H21), F$1, "")) -> FALSE | K21: =IF(SUM(E21:H21)<>0,IF(G21=MIN($E21:$H21), G$1, "")) -> FALSE | L21: =IF(SUM(E21:H21)<>0,IF(H21=MIN($E21:$H21), H$1, "")) -> FALSE

Sheet Response 1
A1: ='Epitome Archetype Guide'!M2 -> Laura | B1: ='Epitome Archetype Guide'!N2 -> Taitz | C1: Company: | D1: ='Epitome Archetype Guide'!P2 -> Fraction PM
A2: Dominant archetype | B2: =Analysis!I2 | C2: =Analysis!J2 -> Empress | D2: =Analysis!K2 | E2: =Analysis!L2
B4: =Reference!A10 -> Leading | C4: =Reference!A11 -> Trust | D4: =Reference!A12 -> Constraints | E4: =Reference!A13 -> Inspiration | F4: =Reference!A14 -> Managing Challenges | G4: =Reference!A15 -> Others View Me | H4: =Reference!A16 -> Striving | I4: =Reference!A17 -> Working With Peers | J4: =Reference!A18 -> At Your Worst | K4: =Reference!A19 -> Confidence | L4: =Reference!A20 -> Power | M4: =Reference!A21 -> Ambition | N4: Total
A5: =Reference!A24 -> Sovereign | B5: ='Epitome Archetype Guide'!S2 -> 3 | C5: ='Epitome Archetype Guide'!U2 -> 1 | D5: ='Epitome Archetype Guide'!Y2 -> 1 | E5: ='Epitome Archetype Guide'!AD2 -> 2 | F5: ='Epitome Archetype Guide'!AJ2 -> 4 | G5: ='Epitome Archetype Guide'!AM2 -> 3 | H5: ='Epitome Archetype Guide'!AO2 -> 1 | I5: ='Epitome Archetype Guide'!AT2 -> 2 | J5: ='Epitome Archetype Guide'!AZ2 -> 4 | K5: ='Epitome Archetype Guide'!BC2 -> 3 | L5: ='Epitome Archetype Guide'!BF2 -> 2 | M5: ='Epitome Archetype Guide'!BL2 -> 4 | N5: =SUM(B5:M5) -> 30
A6: =Reference!A25 -> Empress | B6: ='Epitome Archetype Guide'!R2 -> 2 | C6: ='Epitome Archetype Guide'!V2 -> 2 | D6: ='Epitome Archetype Guide'!AA2 -> 3 | E6: ='Epitome Archetype Guide'!AC2 -> 1 | F6: ='Epitome Archetype Guide'!AG2 -> 1 | G6: ='Epitome Archetype Guide'!AL2 -> 2 | H6: ='Epitome Archetype Guide'!AR2 -> 4 | I6: ='Epitome Archetype Guide'!AS2 -> 1 | J6: ='Epitome Archetype Guide'!AX2 -> 2 | K6: ='Epitome Archetype Guide'!BA2 -> 1 | L6: ='Epitome Archetype Guide'!BE2 -> 1 | M6: ='Epitome Archetype Guide'!BK2 -> 3 | N6: =SUM(B6:M6) -> 23
A7: =Reference!A26 -> Consort | B7: ='Epitome Archetype Guide'!T2 -> 4 | C7: ='Epitome Archetype Guide'!X2 -> 4 | D7: ='Epitome Archetype Guide'!Z2 -> 2 | E7: ='Epitome Archetype Guide'!AE2 -> 3 | F7: ='Epitome Archetype Guide'!AH2 -> 2 | G7: ='Epitome Archetype Guide'!AK2 -> 1 | H7: ='Epitome Archetype Guide'!AP2 -> 2 | I7: ='Epitome Archetype Guide'!AV2 -> 4 | J7: ='Epitome Archetype Guide'!AY2 -> 3 | K7: ='Epitome Archetype Guide'!BD2 -> 4 | L7: ='Epitome Archetype Guide'!BG2 -> 3 | M7: ='Epitome Archetype Guide'!BI2 -> 1 | N7: =SUM(B7:M7) -> 33
A8: =Reference!A27 -> Seductress | B8: ='Epitome Archetype Guide'!Q2 -> 1 | C8: ='Epitome Archetype Guide'!W2 -> 3 | D8: ='Epitome Archetype Guide'!AB2 -> 4 | E8: ='Epitome Archetype Guide'!AF2 -> 4 | F8: ='Epitome Archetype Guide'!AI2 -> 3 | G8: ='Epitome Archetype Guide'!AN2 -> 4 | H8: ='Epitome Archetype Guide'!AQ2 -> 3 | I8: ='Epitome Archetype Guide'!AU2 -> 3 | J8: ='Epitome Archetype Guide'!AW2 -> 1 | K8: ='Epitome Archetype Guide'!BB2 -> 2 | L8: ='Epitome Archetype Guide'!BH2 -> 4 | M8: ='Epitome Archetype Guide'!BJ2 -> 2 | N8: =SUM(B8:M8) -> 34
A11: Inverterd to:
B12: =Reference!A10 -> Leading | C12: =Reference!A11 -> Trust | D12: =Reference!A12 -> Constraints | E12: =Reference!A13 -> Inspiration | F12: =REPT(CHAR(160), 6) & Reference!A14 -> ††††††Managing Challenges | G12: =Reference!A15 -> Others View Me | H12: =Reference!A16 -> Striving | I12: =Reference!A17 -> Working With Peers | J12: =Reference!A18 -> At Your Worst | K12: =Reference!A19 -> Confidence | L12: =Reference!A20 -> Power | M12: =Reference!A21 -> Ambition
A13: =Reference!A24 -> Sovereign | B13: =5-B5 -> 2 | C13: =5-C5 -> 4 | D13: =5-D5 -> 4 | E13: =5-E5 -> 3 | F13: =5-F5 -> 1 | G13: =5-G5 -> 2 | H13: =5-H5 -> 4 | I13: =5-I5 -> 3 | ... M13: =5-M5 -> 1
A14: =Reference!A25 -> Empress | B14: =5-B6 -> 3 | C14: =5-C6 -> 3 | D14: =5-D6 -> 2 | E14: =5-E6 -> 4 | F14: =5-F6 -> 4 | G14: =5-G6 -> 3 | H14: =5-H6 -> 1 | I14: =5-I6 -> 4 | ... M14: =5-M6 -> 2
A15: =Reference!A26 -> Consort | B15: =5-B7 -> 1 | C15: =5-C7 -> 1 | D15: =5-D7 -> 3 | E15: =5-E7 -> 2 | F15: =5-F7 -> 3 | G15: =5-G7 -> 4 | H15: =5-H7 -> 3 | I15: =5-I7 -> 1 | ... M15: =5-M7 -> 4
A16: =Reference!A27 -> Seductress | B16: =5-B8 -> 4 | C16: =5-C8 -> 2 | D16: =5-D8 -> 1 | E16: =5-E8 -> 1 | F16: =5-F8 -> 2 | G16: =5-G8 -> 1 | H16: =5-H8 -> 2 | I16: =5-I8 -> 2 | ... M16: =5-M8 -> 3
B51: =$B$4 -> Leading | C51: =IF(SUM($B$5:$B$8)<>0,IF($B$5=MIN($B$5:$B$8), $A$5, IF(SUM(B5:B8)<>0,IF(B6=MIN($B5:$B8), $A$6, IF(SUM(B5:B8)<>0,IF(B7=MIN($B5:$B8), A7, IF(SUM(B5:B8)<>0,IF(B8=MIN($B5:$B8), A8, "")))))))) -> Seductress
B52: =$C$4 -> Trust | C52: =IF(SUM(C5:C8)<>0,IF(C5=MIN(C5:C8), $A5, IF(SUM(C5:C8)<>0,IF(C6=MIN(C5:C8), $A6, IF(SUM(C5:C8)<>0,IF(C7=MIN(C5:C8), $A7, IF(SUM(C5:C8)<>0,IF(C8=MIN(C5:C8), $A8, "")))))))) -> Sovereign
B53: =$D$4 -> Constraints | C53: =IF(SUM(D5:D8)<>0,IF(D5=MIN(D5:D8), $A5, IF(SUM(D5:D8)<>0,IF(D6=MIN(D5:D8), $A6, IF(SUM(D5:D8)<>0,IF(D7=MIN(D5:D8), $A7, IF(SUM(D5:D8)<>0,IF(D8=MIN(D5:D8), $A8, "")))))))) -> Sovereign
B54: =$E$4 -> Inspiration | C54: =IF(SUM(E5:E8)<>0,IF(E5=MIN(E5:E8), $A5, IF(SUM(E5:E8)<>0,IF(E6=MIN(E5:E8), $A6, IF(SUM(E5:E8)<>0,IF(E7=MIN(E5:E8), $A7, IF(SUM(E5:E8)<>0,IF(E8=MIN(E5:E8), $A8, "")))))))) -> Empress
B55: =$F$4 -> Managing Challenges | C55: =IF(SUM(F5:F8)<>0,IF(F5=MIN(F5:F8), $A5, IF(SUM(F5:F8)<>0,IF(F6=MIN(F5:F8), $A6, IF(SUM(F5:F8)<>0,IF(F7=MIN(F5:F8), $A7, IF(SUM(F5:F8)<>0,IF(F8=MIN(F5:F8), $A8, "")))))))) -> Empress
B56: =$G$4 -> Others View Me | C56: =IF(SUM(G5:G8)<>0,IF(G5=MIN(G5:G8), $A5, IF(SUM(G5:G8)<>0,IF(G6=MIN(G5:G8), $A6, IF(SUM(G5:G8)<>0,IF(G7=MIN(G5:G8), $A7, IF(SUM(G5:G8)<>0,IF(G8=MIN(G5:G8), $A8, "")))))))) -> Consort
B57: =$H$4 -> Striving | C57: =IF(SUM(H5:H8)<>0,IF(H5=MIN(H5:H8), $A5, IF(SUM(H5:H8)<>0,IF(H6=MIN(H5:H8), $A6, IF(SUM(H5:H8)<>0,IF(H7=MIN(H5:H8), $A7, IF(SUM(H5:H8)<>0,IF(H8=MIN(H5:H8), $A8, "")))))))) -> Sovereign
B58: =$I$4 -> Working With Peers | C58: =IF(SUM(I5:I8)<>0,IF(I5=MIN(I5:I8), $A5, IF(SUM(I5:I8)<>0,IF(I6=MIN(I5:I8), $A6, IF(SUM(I5:I8)<>0,IF(I7=MIN(I5:I8), $A7, IF(SUM(I5:I8)<>0,IF(I8=MIN(I5:I8), $A8, "")))))))) -> Empress
B59: =$J$4 -> At Your Worst | C59: =IF(SUM(J5:J8)<>0,IF(J5=MIN(J5:J8), $A5, IF(SUM(J5:J8)<>0,IF(J6=MIN(J5:J8), $A6, IF(SUM(J5:J8)<>0,IF(J7=MIN(J5:J8), $A7, IF(SUM(J5:J8)<>0,IF(J8=MIN(J5:J8), $A8, "")))))))) -> Seductress
B60: =$K$4 -> Confidence | C60: =IF(SUM(K5:K8)<>0,IF(K5=MIN(K5:K8), $A5, IF(SUM(K5:K8)<>0,IF(K6=MIN(K5:K8), $A6, IF(SUM(K5:K8)<>0,IF(K7=MIN(K5:K8), $A7, IF(SUM(K5:K8)<>0,IF(K8=MIN(K5:K8), $A8, "")))))))) -> Empress
B61: =$L$4 -> Power | C61: =IF(SUM(L5:L8)<>0,IF(L5=MIN(L5:L8), $A5, IF(SUM(L5:L8)<>0,IF(L6=MIN(L5:L8), $A6, IF(SUM(L5:L8)<>0,IF(L7=MIN(L5:L8), $A7, IF(SUM(L5:L8)<>0,IF(L8=MIN(L5:L8), $A8, "")))))))) -> Empress
B62: =$M$4 -> Ambition | C62: =IF(SUM(M5:M8)<>0,IF(M5=MIN(M5:M8), $A5, IF(SUM(M5:M8)<>0,IF(M6=MIN(M5:M8), $A6, IF(SUM(M5:M8)<>0,IF(M7=MIN(M5:M8), $A7, IF(SUM(M5:M8)<>0,IF(M8=MIN(M5:M8), $A8, "")))))))) -> Consort

Sheet  Response 2
A1: ='Epitome Archetype Guide'!M3 -> Merle | B1: ='Epitome Archetype Guide'!N3 -> Singer | C1: Company: | D1: ='Epitome Archetype Guide'!P3 -> Epitome Leadership
A2: Dominant archetype | B2: =Analysis!I3 | C2: =Analysis!J3 -> Empress | D2: =Analysis!K3 | E2: =Analysis!L3
B4: =Reference!A10 -> Leading | C4: =Reference!A11 -> Trust | D4: =Reference!A12 -> Constraints | E4: =Reference!A13 -> Inspiration | F4: =Reference!A14 -> Managing Challenges | G4: =Reference!A15 -> Others View Me | H4: =Reference!A16 -> Striving | I4: =Reference!A17 -> Working With Peers | J4: =Reference!A18 -> At Your Worst | K4: =Reference!A19 -> Confidence | L4: =Reference!A20 -> Power | M4: =Reference!A21 -> Ambition | N4: Total
A5: =Reference!A24 -> Sovereign | B5: ='Epitome Archetype Guide'!S3 -> 2 | C5: ='Epitome Archetype Guide'!U3 -> 3 | D5: ='Epitome Archetype Guide'!Y3 -> 1 | E5: ='Epitome Archetype Guide'!AD3 -> 1 | F5: ='Epitome Archetype Guide'!AJ3 -> 4 | G5: ='Epitome Archetype Guide'!AM3 -> 2 | H5: ='Epitome Archetype Guide'!AO3 -> 1 | I5: ='Epitome Archetype Guide'!AT3 -> 3 | J5: ='Epitome Archetype Guide'!AZ3 -> 4 | K5: ='Epitome Archetype Guide'!BC3 -> 2 | L5: ='Epitome Archetype Guide'!BF3 -> 3 | M5: ='Epitome Archetype Guide'!BL3 -> 1 | N5: =SUM(B5:K5) -> 23
A6: =Reference!A25 -> Empress | B6: ='Epitome Archetype Guide'!R3 -> 1 | C6: ='Epitome Archetype Guide'!V3 -> 1 | D6: ='Epitome Archetype Guide'!AA3 -> 2 | E6: ='Epitome Archetype Guide'!AC3 -> 3 | F6: ='Epitome Archetype Guide'!AG3 -> 1 | G6: ='Epitome Archetype Guide'!AL3 -> 1 | H6: ='Epitome Archetype Guide'!AR3 -> 4 | I6: ='Epitome Archetype Guide'!AS3 -> 1 | J6: ='Epitome Archetype Guide'!AX3 -> 3 | K6: ='Epitome Archetype Guide'!BA3 -> 1 | L6: ='Epitome Archetype Guide'!BE3 -> 4 | M6: ='Epitome Archetype Guide'!BK3 -> 2 | N6: =SUM(B6:K6) -> 18
A7: =Reference!A26 -> Consort | B7: ='Epitome Archetype Guide'!T3 -> 3 | C7: ='Epitome Archetype Guide'!X3 -> 2 | D7: ='Epitome Archetype Guide'!Z3 -> 3 | E7: ='Epitome Archetype Guide'!AE3 -> 4 | F7: ='Epitome Archetype Guide'!AH3 -> 3 | G7: ='Epitome Archetype Guide'!AK3 -> 3 | H7: ='Epitome Archetype Guide'!AP3 -> 3 | I7: ='Epitome Archetype Guide'!AV3 -> 4 | J7: ='Epitome Archetype Guide'!AY3 -> 1 | K7: ='Epitome Archetype Guide'!BD3 -> 3 | L7: ='Epitome Archetype Guide'!BG3 -> 1 | M7: ='Epitome Archetype Guide'!BI3 -> 4 | N7: =SUM(B7:K7) -> 29
A8: =Reference!A27 -> Seductress | B8: ='Epitome Archetype Guide'!Q3 -> 4 | C8: ='Epitome Archetype Guide'!W3 -> 4 | D8: ='Epitome Archetype Guide'!AB3 -> 4 | E8: ='Epitome Archetype Guide'!AF3 -> 2 | F8: ='Epitome Archetype Guide'!AI3 -> 2 | G8: ='Epitome Archetype Guide'!AN3 -> 4 | H8: ='Epitome Archetype Guide'!AQ3 -> 2 | I8: ='Epitome Archetype Guide'!AU3 -> 2 | J8: ='Epitome Archetype Guide'!AW3 -> 2 | K8: ='Epitome Archetype Guide'!BB3 -> 4 | L8: ='Epitome Archetype Guide'!BH3 -> 2 | M8: ='Epitome Archetype Guide'!BJ3 -> 3 | N8: =SUM(B8:K8) -> 30
A11: Inverterd to:
B12: =Reference!A10 -> Leading | C12: =Reference!A11 -> Trust | D12: =Reference!A12 -> Constraints | E12: =Reference!A13 -> Inspiration | F12: =REPT(CHAR(160), 6) & Reference!A14 -> ††††††Managing Challenges | G12: =Reference!A15 -> Others View Me | H12: =Reference!A16 -> Striving | I12: =Reference!A17 -> Working With Peers | J12: =Reference!A18 -> At Your Worst | K12: =Reference!A19 -> Confidence | L12: =Reference!A20 -> Power | M12: =Reference!A21 -> Ambition
A13: =Reference!A24 -> Sovereign | B13: =5-B5 -> 3 | C13: =5-C5 -> 2 | D13: =5-D5 -> 4 | E13: =5-E5 -> 4 | F13: =5-F5 -> 1 | G13: =5-G5 -> 3 | H13: =5-H5 -> 4 | I13: =5-I5 -> 2 | ... M13: =5-M5 -> 4
A14: =Reference!A25 -> Empress | B14: =5-B6 -> 4 | C14: =5-C6 -> 4 | D14: =5-D6 -> 3 | E14: =5-E6 -> 2 | F14: =5-F6 -> 4 | G14: =5-G6 -> 4 | H14: =5-H6 -> 1 | I14: =5-I6 -> 4 | ... M14: =5-M6 -> 3
A15: =Reference!A26 -> Consort | B15: =5-B7 -> 2 | C15: =5-C7 -> 3 | D15: =5-D7 -> 2 | E15: =5-E7 -> 1 | F15: =5-F7 -> 2 | G15: =5-G7 -> 2 | H15: =5-H7 -> 2 | I15: =5-I7 -> 1 | ... M15: =5-M7 -> 1
A16: =Reference!A27 -> Seductress | B16: =5-B8 -> 1 | C16: =5-C8 -> 1 | D16: =5-D8 -> 1 | E16: =5-E8 -> 3 | F16: =5-F8 -> 3 | G16: =5-G8 -> 1 | H16: =5-H8 -> 3 | I16: =5-I8 -> 3 | ... M16: =5-M8 -> 2
B51: =$B$4 -> Leading | C51: =IF(SUM($B$5:$B$8)<>0,IF($B$5=MIN($B$5:$B$8), $A$5, IF(SUM(B5:B8)<>0,IF(B6=MIN($B5:$B8), $A$6, IF(SUM(B5:B8)<>0,IF(B7=MIN($B5:$B8), A7, IF(SUM(B5:B8)<>0,IF(B8=MIN($B5:$B8), A8, "")))))))) -> Empress
B52: =$C$4 -> Trust | C52: =IF(SUM(C5:C8)<>0,IF(C5=MIN(C5:C8), $A5, IF(SUM(C5:C8)<>0,IF(C6=MIN(C5:C8), $A6, IF(SUM(C5:C8)<>0,IF(C7=MIN(C5:C8), $A7, IF(SUM(C5:C8)<>0,IF(C8=MIN(C5:C8), $A8, "")))))))) -> Empress
B53: =$D$4 -> Constraints | C53: =IF(SUM(D5:D8)<>0,IF(D5=MIN(D5:D8), $A5, IF(SUM(D5:D8)<>0,IF(D6=MIN(D5:D8), $A6, IF(SUM(D5:D8)<>0,IF(D7=MIN(D5:D8), $A7, IF(SUM(D5:D8)<>0,IF(D8=MIN(D5:D8), $A8, "")))))))) -> Sovereign
B54: =$E$4 -> Inspiration | C54: =IF(SUM(E5:E8)<>0,IF(E5=MIN(E5:E8), $A5, IF(SUM(E5:E8)<>0,IF(E6=MIN(E5:E8), $A6, IF(SUM(E5:E8)<>0,IF(E7=MIN(E5:E8), $A7, IF(SUM(E5:E8)<>0,IF(E8=MIN(E5:E8), $A8, "")))))))) -> Sovereign
